# HerramientasParaElManejoDeErrores
Honestamente no encontre alguna herramienta de manejo de errores que fuera posible implementar y representar visualmente en este repositorio, es por ello que decidí emplear la misma herramienta del try-catch, solo que en esta ocasión esta será implementada en C++ y se hará uso del debugger GDB para visualizar todos los datos que el compilador toma en cuenta al momento de ejecutar y compilar el código.
Se colocaron 4 breakpoints al momento de usar el debugger; esto para detener el código en puntos cruciales de la ejecución y para obvservar como el compilador trata las variables. El primer breakpoint se encuentra en la línea 28, en el primer bloque 'try-catch', especifícamente al inicio del 'try'; después de unos 'step-into' se puede ver a la izqueirda en la sección de variables que 'a' y 'b' así como 'result' cuentan con un valor asignado. 'a' y 'b' tienen los valores que se especificaron manualmente por nosotros para ellos y 'result' es el valor de la operación 'a'/'b' (al ser enteros todos, el resultado no cuenta con punto decimal).
El siguiente breakpoint se econtraba en el 'catch' de este primer bloque, pero al no ser requerido por el 'try', este breakpoint es ignorado y el debugger pasa al siguiente.
![Screenshot_20230128_114706](https://user-images.githubusercontent.com/80866790/215282699-30e99605-ebb0-4d25-9055-dcce93d9999d.png)
El tercer breakpoint se encuentra en el 'try' del segundo bloque 'try-catch'. En la captura se ve que ya pasó por la función 'divide' y está en el útimo breakpoint que se encuentra en el 'catch'. Algo importante a notar es que la variable 'result' a la izquierda no cambió de valor, esto es porque al entrar en la función 'divide' se revisa si el divisor es distinto a '0' y si no lo es, no se realiza la división y se arroja el 'runtime_error' de "Error: división por cero"; esto hace que el 'catch' de este bloque reciba el error arrojado por la función y lo muestre en pantalla en lugar de terminar de ejecutar la sección 'try' y mostrar el resultado.
![Screenshot_20230128_114729](https://user-images.githubusercontent.com/80866790/215282713-081c9e6b-af5b-4be0-b74f-48a421430db6.png)
Por último, se observa en la sección de la terminal (parte inferior de la captura) que hay dos mensajes: el resultado de la operación válida y el 'runtime_error' de la operación inválida.
![Screenshot_20230128_114739](https://user-images.githubusercontent.com/80866790/215282716-2d7dcc93-6f24-488f-bca2-6b243587e6f7.png)
